Workbook
Name Slicer_Customer_Type: #N/A
Name Slicer_Region: #N/A
Name Slicer_Sale_Date__Month: #N/A
Name Slicer_Sales_Channel: #N/A

Sheet DASHBOARD

Sheet Cleaned Sales
A1: Product_ID | B1: Sale_Date | C1: Sales_Rep | D1: Region | E1: Sales_Amount | F1: Quantity_Sold | G1: Product_Category | H1: Unit_Cost | I1: Unit_Price | J1: Customer_Type | K1: Discount | L1: Payment_Method | M1: Sales_Channel
A2: 1052 | B2: 45235 | C2: =IF(ISBLANK(Table14[[#This Row],[Sales_Rep]]),"Unknown",Table14[[#This Row],[Sales_Rep]]) -> David | D2: =PROPER(Table14[[#This Row],[Region]]) -> East | E2: =IF(ISBLANK(Table14[[#This Row],[Sales_Amount]]),MEDIAN(Table14[Sales_Amount]),Table14[[#This Row],[Sales_Amount]]) -> 71951.51 | F2: =IF(ISBLANK(Table14[[#This Row],[Quantity_Sold]]),MEDIAN(Table14[Quantity_Sold]),Table14[[#This Row],[Quantity_Sold]]) -> 48 | G2: =TRIM(Table14[[#This Row],[Product_Category]]) -> Food | H2: 1147.38 | I2: 1594.67 | J2: =PROPER(Table14[[#This Row],[Customer_Type]]) -> Returning | K2: =IF(ISBLANK(Table14[[#This Row],[Discount]]),MEDIAN(Table14[Discount]),Table14[[#This Row],[Discount]]) -> 0.06 | L2: Credit Card | M2: Retail
A3: 1301 | B3: 45344 | C3: =IF(ISBLANK(Table14[[#This Row],[Sales_Rep]]),"Unknown",Table14[[#This Row],[Sales_Rep]]) -> Unknown | D3: =PROPER(Table14[[#This Row],[Region]]) -> North | E3: =IF(ISBLANK(Table14[[#This Row],[Sales_Amount]]),MEDIAN(Table14[Sales_Amount]),Table14[[#This Row],[Sales_Amount]]) -> 8444.02 | F3: =IF(ISBLANK(Table14[[#This Row],[Quantity_Sold]]),MEDIAN(Table14[Quantity_Sold]),Table14[[#This Row],[Quantity_Sold]]) -> 20 | G3: =TRIM(Table14[[#This Row],[Product_Category]]) -> Electronics | H3: 451.85 | I3: 586.39 | J3: =PROPER(Table14[[#This Row],[Customer_Type]]) -> Returning | K3: =IF(ISBLANK(Table14[[#This Row],[Discount]]),MEDIAN(Table14[Discount]),Table14[[#This Row],[Discount]]) -> 0.15 | L3: Credit Card | M3: Online
A4: 1426 | B4: 44955 | C4: =IF(ISBLANK(Table14[[#This Row],[Sales_Rep]]),"Unknown",Table14[[#This Row],[Sales_Rep]]) -> Charlie | D4: =PROPER(Table14[[#This Row],[Region]]) -> East | E4: =IF(ISBLANK(Table14[[#This Row],[Sales_Amount]]),MEDIAN(Table14[Sales_Amount]),Table14[[#This Row],[Sales_Amount]]) -> 50770.89 | F4: =IF(ISBLANK(Table14[[#This Row],[Quantity_Sold]]),MEDIAN(Table14[Quantity_Sold]),Table14[[#This Row],[Quantity_Sold]]) -> 36 | G4: =TRIM(Table14[[#This Row],[Product_Category]]) -> Clothing | H4: 1554.12 | I4: 2130.42 | J4: =PROPER(Table14[[#This Row],[Customer_Type]]) -> New | K4: =IF(ISBLANK(Table14[[#This Row],[Discount]]),MEDIAN(Table14[Discount]),Table14[[#This Row],[Discount]]) -> 0.28 | L4: Bank Transfer | M4: Retail
A5: 1170 | B5: 44981 | C5: =IF(ISBLANK(Table14[[#This Row],[Sales_Rep]]),"Unknown",Table14[[#This Row],[Sales_Rep]]) -> Eve | D5: =PROPER(Table14[[#This Row],[Region]]) -> West | E5: =IF(ISBLANK(Table14[[#This Row],[Sales_Amount]]),MEDIAN(Table14[Sales_Amount]),Table14[[#This Row],[Sales_Amount]]) -> 73691.05 | F5: =IF(ISBLANK(Table14[[#This Row],[Quantity_Sold]]),MEDIAN(Table14[Quantity_Sold]),Table14[[#This Row],[Quantity_Sold]]) -> 25 | G5: =TRIM(Table14[[#This Row],[Product_Category]]) -> Clothing | H5: 1733.8 | I5: 2477.01 | J5: =PROPER(Table14[[#This Row],[Customer_Type]]) -> Returning | K5: =IF(ISBLANK(Table14[[#This Row],[Discount]]),MEDIAN(Table14[Discount]),Table14[[#This Row],[Discount]]) -> 0.15 | L5: Credit Card | M5: Online
A6: 1019 | B6: 45263 | C6: =IF(ISBLANK(Table14[[#This Row],[Sales_Rep]]),"Unknown",Table14[[#This Row],[Sales_Rep]]) -> Eve | D6: =PROPER(Table14[[#This Row],[Region]]) -> East | E6: =IF(ISBLANK(Table14[[#This Row],[Sales_Amount]]),MEDIAN(Table14[Sales_Amount]),Table14[[#This Row],[Sales_Amount]]) -> 99978.16 | F6: =IF(ISBLANK(Table14[[#This Row],[Quantity_Sold]]),MEDIAN(Table14[Quantity_Sold]),Table14[[#This Row],[Quantity_Sold]]) -> 33 | G6: =TRIM(Table14[[#This Row],[Product_Category]]) -> Furniture | H6: 2593.01 | I6: 3650.17 | J6: =PROPER(Table14[[#This Row],[Customer_Type]]) -> Returning | K6: =IF(ISBLANK(Table14[[#This Row],[Discount]]),MEDIAN(Table14[Discount]),Table14[[#This Row],[Discount]]) -> 0.17 | L6: Credit Card | M6: Retail
A7: 1239 | B7: 45630 | C7: =IF(ISBLANK(Table14[[#This Row],[Sales_Rep]]),"Unknown",Table14[[#This Row],[Sales_Rep]]) -> Bob | D7: =PROPER(Table14[[#This Row],[Region]]) -> North | E7: =IF(ISBLANK(Table14[[#This Row],[Sales_Amount]]),MEDIAN(Table14[Sales_Amount]),Table14[[#This Row],[Sales_Amount]]) -> 18064.11 | F7: =IF(ISBLANK(Table14[[#This Row],[Quantity_Sold]]),MEDIAN(Table14[Quantity_Sold]),Table14[[#This Row],[Quantity_Sold]]) -> 12 | G7: =TRIM(Table14[[#This Row],[Product_Category]]) -> Clothing | H7: 1528.85 | I7: 1954.99 | J7: =PROPER(Table14[[#This Row],[Customer_Type]]) -> New | K7: =IF(ISBLANK(Table14[[#This Row],[Discount]]),MEDIAN(Table14[Discount]),Table14[[#This Row],[Discount]]) -> 0.23 | L7: Bank Transfer | M7: Retail
A8: 1452 | B8: 45010 | C8: =IF(ISBLANK(Table14[[#This Row],[Sales_Rep]]),"Unknown",Table14[[#This Row],[Sales_Rep]]) -> Unknown | D8: =PROPER(Table14[[#This Row],[Region]]) -> East | E8: =IF(ISBLANK(Table14[[#This Row],[Sales_Amount]]),MEDIAN(Table14[Sales_Amount]),Table14[[#This Row],[Sales_Amount]]) -> 61782.11 | F8: =IF(ISBLANK(Table14[[#This Row],[Quantity_Sold]]),MEDIAN(Table14[Quantity_Sold]),Table14[[#This Row],[Quantity_Sold]]) -> 15 | G8: =TRIM(Table14[[#This Row],[Product_Category]]) -> Food | H8: 4099.54 | I8: 5213.68 | J8: =PROPER(Table14[[#This Row],[Customer_Type]]) -> Returning | K8: =IF(ISBLANK(Table14[[#This Row],[Discount]]),MEDIAN(Table14[Discount]),Table14[[#This Row],[Discount]]) -> 0.21 | L8: Credit Card | M8: Retail
A9: 1318 | B9: 45124 | C9: =IF(ISBLANK(Table14[[#This Row],[Sales_Rep]]),"Unknown",Table14[[#This Row],[Sales_Rep]]) -> Charlie | D9: =PROPER(Table14[[#This Row],[Region]]) -> East | E9: =IF(ISBLANK(Table14[[#This Row],[Sales_Amount]]),MEDIAN(Table14[Sales_Amount]),Table14[[#This Row],[Sales_Amount]]) -> 160204.34 | F9: =IF(ISBLANK(Table14[[#This Row],[Quantity_Sold]]),MEDIAN(Table14[Quantity_Sold]),Table14[[#This Row],[Quantity_Sold]]) -> 45 | G9: =TRIM(Table14[[#This Row],[Product_Category]]) -> Food | H9: 2736.72 | I9: 3747.47 | J9: =PROPER(Table14[[#This Row],[Customer_Type]]) -> New | K9: =IF(ISBLANK(Table14[[#This Row],[Discount]]),MEDIAN(Table14[Discount]),Table14[[#This Row],[Discount]]) -> 0.15 | L9: Credit Card | M9: Online
A10: 1463 | B10: 45192 | C10: =IF(ISBLANK(Table14[[#This Row],[Sales_Rep]]),"Unknown",Table14[[#This Row],[Sales_Rep]]) -> Charlie | D10: =PROPER(Table14[[#This Row],[Region]]) -> East | E10: =IF(ISBLANK(Table14[[#This Row],[Sales_Amount]]),MEDIAN(Table14[Sales_Amount]),Table14[[#This Row],[Sales_Amount]]) -> 29967.11 | F10: =IF(ISBLANK(Table14[[#This Row],[Quantity_Sold]]),MEDIAN(Table14[Quantity_Sold]),Table14[[#This Row],[Quantity_Sold]]) -> 18 | G10: =TRIM(Table14[[#This Row],[Product_Category]]) -> Electronics | H10: 1686.82 | I10: 1935.86 | J10: =PROPER(Table14[[#This Row],[Customer_Type]]) -> Returning | K10: =IF(ISBLANK(Table14[[#This Row],[Discount]]),MEDIAN(Table14[Discount]),Table14[[#This Row],[Discount]]) -> 0.15 | L10: Bank Transfer | M10: Online
A11: 1427 | B11: 45297 | C11: =IF(ISBLANK(Table14[[#This Row],[Sales_Rep]]),"Unknown",Table14[[#This Row],[Sales_Rep]]) -> Eve | D11: =PROPER(Table14[[#This Row],[Region]]) -> West | E11: =IF(ISBLANK(Table14[[#This Row],[Sales_Amount]]),MEDIAN(Table14[Sales_Amount]),Table14[[#This Row],[Sales_Amount]]) -> 68837.01 | F11: =IF(ISBLANK(Table14[[#This Row],[Quantity_Sold]]),MEDIAN(Table14[Quantity_Sold]),Table14[[#This Row],[Quantity_Sold]]) -> 28 | G11: =TRIM(Table14[[#This Row],[Product_Category]]) -> Food | H11: 2549.57 | I11: 3367.76 | J11: =PROPER(Table14[[#This Row],[Customer_Type]]) -> Returning | K11: =IF(ISBLANK(Table14[[#This Row],[Discount]]),MEDIAN(Table14[Discount]),Table14[[#This Row],[Discount]]) -> 0.27 | L11: Credit Card | M11: Retail
A12: 1455 | B12: 45319 | C12: =IF(ISBLANK(Table14[[#This Row],[Sales_Rep]]),"Unknown",Table14[[#This Row],[Sales_Rep]]) -> David | D12: =PROPER(Table14[[#This Row],[Region]]) -> South | E12: =IF(ISBLANK(Table14[[#This Row],[Sales_Amount]]),MEDIAN(Table14[Sales_Amount]),Table14[[#This Row],[Sales_Amount]]) -> 50770.89 | F12: =IF(ISBLANK(Table14[[#This Row],[Quantity_Sold]]),MEDIAN(Table14[Quantity_Sold]),Table14[[#This Row],[Quantity_Sold]]) -> 50 | G12: =TRIM(Table14[[#This Row],[Product_Category]]) -> Clothing | H12: 3254.81 | I12: 4805.11 | J12: =PROPER(Table14[[#This Row],[Customer_Type]]) -> Returning | K12: =IF(ISBLANK(Table14[[#This Row],[Discount]]),MEDIAN(Table14[Discount]),Table14[[#This Row],[Discount]]) -> 0.17 | L12: Cash | M12: Retail
A13: 1409 | B13: 45318 | C13: =IF(ISBLANK(Table14[[#This Row],[Sales_Rep]]),"Unknown",Table14[[#This Row],[Sales_Rep]]) -> Unknown | D13: =PROPER(Table14[[#This Row],[Region]]) -> South | E13: =IF(ISBLANK(Table14[[#This Row],[Sales_Amount]]),MEDIAN(Table14[Sales_Amount]),Table14[[#This Row],[Sales_Amount]]) -> 4650.09 | F13: =IF(ISBLANK(Table14[[#This Row],[Quantity_Sold]]),MEDIAN(Table14[Quantity_Sold]),Table14[[#This Row],[Quantity_Sold]]) -> 25 | G13: =TRIM(Table14[[#This Row],[Product_Category]]) -> Electronics | H13: 3767.42 | I13: 4744.99 | J13: =PROPER(Table14[[#This Row],[Customer_Type]]) -> Returning | K13: =IF(ISBLANK(Table14[[#This Row],[Discount]]),MEDIAN(Table14[Discount]),Table14[[#This Row],[Discount]]) -> 0.02 | L13: Cash | M13: Retail
... A409: 1316 | B409: 45573 | C409: =IF(ISBLANK(Table14[[#This Row],[Sales_Rep]]),"Unknown",Table14[[#This Row],[Sales_Rep]]) -> David | D409: =PROPER(Table14[[#This Row],[Region]]) -> South | E409: =IF(ISBLANK(Table14[[#This Row],[Sales_Amount]]),MEDIAN(Table14[Sales_Amount]),Table14[[#This Row],[Sales_Amount]]) -> 37152.72 | F409: =IF(ISBLANK(Table14[[#This Row],[Quantity_Sold]]),MEDIAN(Table14[Quantity_Sold]),Table14[[#This Row],[Quantity_Sold]]) -> 45 | G409: =TRIM(Table14[[#This Row],[Product_Category]]) -> Furniture | H409: 817.38 | I409: 938.2 | J409: =PROPER(Table14[[#This Row],[Customer_Type]]) -> Returning | K409: =IF(ISBLANK(Table14[[#This Row],[Discount]]),MEDIAN(Table14[Discount]),Table14[[#This Row],[Discount]]) -> 0.12 | L409: Bank Transfer | M409: Online
A410: 1346 | B410: 45640 | C410: =IF(ISBLANK(Table14[[#This Row],[Sales_Rep]]),"Unknown",Table14[[#This Row],[Sales_Rep]]) -> Eve | D410: East | E410: =IF(ISBLANK(Table14[[#This Row],[Sales_Amount]]),MEDIAN(Table14[Sales_Amount]),Table14[[#This Row],[Sales_Amount]]) -> 2026.33 | F410: =IF(ISBLANK(Table14[[#This Row],[Quantity_Sold]]),MEDIAN(Table14[Quantity_Sold]),Table14[[#This Row],[Quantity_Sold]]) -> 7 | G410: =TRIM(Table14[[#This Row],[Product_Category]]) -> Furniture | H410: 274.96 | I410: 332.73 | J410: =PROPER(Table14[[#This Row],[Customer_Type]]) -> Returning | K410: =IF(ISBLANK(Table14[[#This Row],[Discount]]),MEDIAN(Table14[Discount]),Table14[[#This Row],[Discount]]) -> 0.13 | L410: Cash | M410: Retail
A411: 1280 | B411: 45496 | C411: =IF(ISBLANK(Table14[[#This Row],[Sales_Rep]]),"Unknown",Table14[[#This Row],[Sales_Rep]]) -> David | D411: =PROPER(Table14[[#This Row],[Region]]) -> East | E411: =IF(ISBLANK(Table14[[#This Row],[Sales_Amount]]),MEDIAN(Table14[Sales_Amount]),Table14[[#This Row],[Sales_Amount]]) -> 27005.66 | F411: =IF(ISBLANK(Table14[[#This Row],[Quantity_Sold]]),MEDIAN(Table14[Quantity_Sold]),Table14[[#This Row],[Quantity_Sold]]) -> 22 | G411: =TRIM(Table14[[#This Row],[Product_Category]]) -> Clothing | H411: 951.45 | I411: 1227.53 | J411: =PROPER(Table14[[#This Row],[Customer_Type]]) -> Returning | K411: =IF(ISBLANK(Table14[[#This Row],[Discount]]),MEDIAN(Table14[Discount]),Table14[[#This Row],[Discount]]) -> 0 | L411: Bank Transfer | M411: Online
A412: 1004 | B412: 45575 | C412: =IF(ISBLANK(Table14[[#This Row],[Sales_Rep]]),"Unknown",Table14[[#This Row],[Sales_Rep]]) -> Bob | D412: =PROPER(Table14[[#This Row],[Region]]) -> North | E412: =IF(ISBLANK(Table14[[#This Row],[Sales_Amount]]),MEDIAN(Table14[Sales_Amount]),Table14[[#This Row],[Sales_Amount]]) -> 160343.9 | F412: =IF(ISBLANK(Table14[[#This Row],[Quantity_Sold]]),MEDIAN(Table14[Quantity_Sold]),Table14[[#This Row],[Quantity_Sold]]) -> 39 | G412: =TRIM(Table14[[#This Row],[Product_Category]]) -> Clothing | H412: 3562.56 | I412: 4836.92 | J412: =PROPER(Table14[[#This Row],[Customer_Type]]) -> Returning | K412: =IF(ISBLANK(Table14[[#This Row],[Discount]]),MEDIAN(Table14[Discount]),Table14[[#This Row],[Discount]]) -> 0.15 | L412: Credit Card | M412: Retail
A413: 1107 | B413: 45482 | C413: =IF(ISBLANK(Table14[[#This Row],[Sales_Rep]]),"Unknown",Table14[[#This Row],[Sales_Rep]]) -> Bob | D413: =PROPER(Table14[[#This Row],[Region]]) -> East | E413: =IF(ISBLANK(Table14[[#This Row],[Sales_Amount]]),MEDIAN(Table14[Sales_Amount]),Table14[[#This Row],[Sales_Amount]]) -> 16395.28 | F413: =IF(ISBLANK(Table14[[#This Row],[Quantity_Sold]]),MEDIAN(Table14[Quantity_Sold]),Table14[[#This Row],[Quantity_Sold]]) -> 6 | G413: =TRIM(Table14[[#This Row],[Product_Category]]) -> Food | H413: 2278.1 | I413: 3214.76 | J413: =PROPER(Table14[[#This Row],[Customer_Type]]) -> Returning | K413: =IF(ISBLANK(Table14[[#This Row],[Discount]]),MEDIAN(Table14[Discount]),Table14[[#This Row],[Discount]]) -> 0.15 | L413: Credit Card | M413: Retail
A414: 1259 | B414: 45240 | C414: =IF(ISBLANK(Table14[[#This Row],[Sales_Rep]]),"Unknown",Table14[[#This Row],[Sales_Rep]]) -> Eve | D414: =PROPER(Table14[[#This Row],[Region]]) -> East | E414: =IF(ISBLANK(Table14[[#This Row],[Sales_Amount]]),MEDIAN(Table14[Sales_Amount]),Table14[[#This Row],[Sales_Amount]]) -> 36234.89 | F414: =IF(ISBLANK(Table14[[#This Row],[Quantity_Sold]]),MEDIAN(Table14[Quantity_Sold]),Table14[[#This Row],[Quantity_Sold]]) -> 9 | G414: =TRIM(Table14[[#This Row],[Product_Category]]) -> Food | H414: 4603.19 | I414: 5751.57 | J414: =PROPER(Table14[[#This Row],[Customer_Type]]) -> Returning | K414: =IF(ISBLANK(Table14[[#This Row],[Discount]]),MEDIAN(Table14[Discount]),Table14[[#This Row],[Discount]]) -> 0.3 | L414: Cash | M414: Retail
A415: 1229 | B415: 45609 | C415: =IF(ISBLANK(Table14[[#This Row],[Sales_Rep]]),"Unknown",Table14[[#This Row],[Sales_Rep]]) -> David | D415: =PROPER(Table14[[#This Row],[Region]]) -> North | E415: =IF(ISBLANK(Table14[[#This Row],[Sales_Amount]]),MEDIAN(Table14[Sales_Amount]),Table14[[#This Row],[Sales_Amount]]) -> 50490.94 | F415: =IF(ISBLANK(Table14[[#This Row],[Quantity_Sold]]),MEDIAN(Table14[Quantity_Sold]),Table14[[#This Row],[Quantity_Sold]]) -> 25 | G415: =TRIM(Table14[[#This Row],[Product_Category]]) -> Electronics | H415: 1112.64 | I415: 1471.61 | J415: =PROPER(Table14[[#This Row],[Customer_Type]]) -> New | K415: =IF(ISBLANK(Table14[[#This Row],[Discount]]),MEDIAN(Table14[Discount]),Table14[[#This Row],[Discount]]) -> 0.27 | L415: Cash | M415: Online
A416: 1181 | B416: 45384 | C416: =IF(ISBLANK(Table14[[#This Row],[Sales_Rep]]),"Unknown",Table14[[#This Row],[Sales_Rep]]) -> Alice | D416: =PROPER(Table14[[#This Row],[Region]]) -> West | E416: =IF(ISBLANK(Table14[[#This Row],[Sales_Amount]]),MEDIAN(Table14[Sales_Amount]),Table14[[#This Row],[Sales_Amount]]) -> 86255.95 | F416: =IF(ISBLANK(Table14[[#This Row],[Quantity_Sold]]),MEDIAN(Table14[Quantity_Sold]),Table14[[#This Row],[Quantity_Sold]]) -> 48 | G416: =TRIM(Table14[[#This Row],[Product_Category]]) -> Clothing | H416: 1427.6 | I416: 2019.1 | J416: =PROPER(Table14[[#This Row],[Customer_Type]]) -> Returning | K416: =IF(ISBLANK(Table14[[#This Row],[Discount]]),MEDIAN(Table14[Discount]),Table14[[#This Row],[Discount]]) -> 0.11 | L416: Cash | M416: Retail
A417: 1340 | B417: 45433 | C417: =IF(ISBLANK(Table14[[#This Row],[Sales_Rep]]),"Unknown",Table14[[#This Row],[Sales_Rep]]) -> Eve | D417: =PROPER(Table14[[#This Row],[Region]]) -> East | E417: =IF(ISBLANK(Table14[[#This Row],[Sales_Amount]]),MEDIAN(Table14[Sales_Amount]),Table14[[#This Row],[Sales_Amount]]) -> 1986.17 | F417: =IF(ISBLANK(Table14[[#This Row],[Quantity_Sold]]),MEDIAN(Table14[Quantity_Sold]),Table14[[#This Row],[Quantity_Sold]]) -> 23 | G417: =TRIM(Table14[[#This Row],[Product_Category]]) -> Furniture | H417: 80.79 | I417: 90.9 | J417: =PROPER(Table14[[#This Row],[Customer_Type]]) -> Returning | K417: =IF(ISBLANK(Table14[[#This Row],[Discount]]),MEDIAN(Table14[Discount]),Table14[[#This Row],[Discount]]) -> 0.05 | L417: Credit Card | M417: Online
A418: 1182 | B418: 45509 | C418: =IF(ISBLANK(Table14[[#This Row],[Sales_Rep]]),"Unknown",Table14[[#This Row],[Sales_Rep]]) -> Bob | D418: =PROPER(Table14[[#This Row],[Region]]) -> North | E418: =IF(ISBLANK(Table14[[#This Row],[Sales_Amount]]),MEDIAN(Table14[Sales_Amount]),Table14[[#This Row],[Sales_Amount]]) -> 68193.22 | F418: =IF(ISBLANK(Table14[[#This Row],[Quantity_Sold]]),MEDIAN(Table14[Quantity_Sold]),Table14[[#This Row],[Quantity_Sold]]) -> 28 | G418: =TRIM(Table14[[#This Row],[Product_Category]]) -> Clothing | H418: 2942.48 | I418: 3382.6 | J418: =PROPER(Table14[[#This Row],[Customer_Type]]) -> New | K418: =IF(ISBLANK(Table14[[#This Row],[Discount]]),MEDIAN(Table14[Discount]),Table14[[#This Row],[Discount]]) -> 0.28 | L418: Credit Card | M418: Online
A419: 1411 | B419: 45478 | C419: =IF(ISBLANK(Table14[[#This Row],[Sales_Rep]]),"Unknown",Table14[[#This Row],[Sales_Rep]]) -> Bob | D419: =PROPER(Table14[[#This Row],[Region]]) -> East | E419: =IF(ISBLANK(Table14[[#This Row],[Sales_Amount]]),MEDIAN(Table14[Sales_Amount]),Table14[[#This Row],[Sales_Amount]]) -> 144251.98 | F419: =IF(ISBLANK(Table14[[#This Row],[Quantity_Sold]]),MEDIAN(Table14[Quantity_Sold]),Table14[[#This Row],[Quantity_Sold]]) -> 49 | G419: =TRIM(Table14[[#This Row],[Product_Category]]) -> Furniture | H419: 2525.82 | I419: 3271.02 | J419: =PROPER(Table14[[#This Row],[Customer_Type]]) -> New | K419: =IF(ISBLANK(Table14[[#This Row],[Discount]]),MEDIAN(Table14[Discount]),Table14[[#This Row],[Discount]]) -> 0.1 | L419: Bank Transfer | M419: Online
A420: 1241 | B420: 45327 | C420: =IF(ISBLANK(Table14[[#This Row],[Sales_Rep]]),"Unknown",Table14[[#This Row],[Sales_Rep]]) -> Eve | D420: =PROPER(Table14[[#This Row],[Region]]) -> South | E420: =IF(ISBLANK(Table14[[#This Row],[Sales_Amount]]),MEDIAN(Table14[Sales_Amount]),Table14[[#This Row],[Sales_Amount]]) -> 90816.88 | F420: =IF(ISBLANK(Table14[[#This Row],[Quantity_Sold]]),MEDIAN(Table14[Quantity_Sold]),Table14[[#This Row],[Quantity_Sold]]) -> 15 | G420: =TRIM(Table14[[#This Row],[Product_Category]]) -> Food | H420: 4420.32 | I420: 6241.71 | J420: =PROPER(Table14[[#This Row],[Customer_Type]]) -> Returning | K420: =IF(ISBLANK(Table14[[#This Row],[Discount]]),MEDIAN(Table14[Discount]),Table14[[#This Row],[Discount]]) -> 0.03 | L420: Bank Transfer | M420: Retail
A421: 1464 | B421: 45216 | C421: =IF(ISBLANK(Table14[[#This Row],[Sales_Rep]]),"Unknown",Table14[[#This Row],[Sales_Rep]]) -> David | D421: =PROPER(Table14[[#This Row],[Region]]) -> North | E421: =IF(ISBLANK(Table14[[#This Row],[Sales_Amount]]),MEDIAN(Table14[Sales_Amount]),Table14[[#This Row],[Sales_Amount]]) -> 27506.45 | F421: =IF(ISBLANK(Table14[[#This Row],[Quantity_Sold]]),MEDIAN(Table14[Quantity_Sold]),Table14[[#This Row],[Quantity_Sold]]) -> 8 | G421: =TRIM(Table14[[#This Row],[Product_Category]]) -> Clothing | H421: 2970.29 | I421: 3820.34 | J421: =PROPER(Table14[[#This Row],[Customer_Type]]) -> New | K421: =IF(ISBLANK(Table14[[#This Row],[Discount]]),MEDIAN(Table14[Discount]),Table14[[#This Row],[Discount]]) -> 0.1 | L421: Cash | M421: Retail
A422: 1223 | B422: 44991 | C422: =IF(ISBLANK(Table14[[#This Row],[Sales_Rep]]),"Unknown",Table14[[#This Row],[Sales_Rep]]) -> Bob | D422: =PROPER(Table14[[#This Row],[Region]]) -> East | E422: =IF(ISBLANK(Table14[[#This Row],[Sales_Amount]]),MEDIAN(Table14[Sales_Amount]),Table14[[#This Row],[Sales_Amount]]) -> 53754.5 | F422: =IF(ISBLANK(Table14[[#This Row],[Quantity_Sold]]),MEDIAN(Table14[Quantity_Sold]),Table14[[#This Row],[Quantity_Sold]]) -> 16 | G422: =TRIM(Table14[[#This Row],[Product_Category]]) -> Electronics | H422: 2897.26 | I422: 3651.8 | J422: =PROPER(Table14[[#This Row],[Customer_Type]]) -> Returning | K422: =IF(ISBLANK(Table14[[#This Row],[Discount]]),MEDIAN(Table14[Discount]),Table14[[#This Row],[Discount]]) -> 0.08 | L422: Credit Card | M422: Retail
... A4551: 1267 | B4551: 44961 | C4551: =IF(ISBLANK(Table14[[#This Row],[Sales_Rep]]),"Unknown",Table14[[#This Row],[Sales_Rep]]) -> David | D4551: =PROPER(Table14[[#This Row],[Region]]) -> East | E4551: =IF(ISBLANK(Table14[[#This Row],[Sales_Amount]]),MEDIAN(Table14[Sales_Amount]),Table14[[#This Row],[Sales_Amount]]) -> 5962.63 | F4551: =IF(ISBLANK(Table14[[#This Row],[Quantity_Sold]]),MEDIAN(Table14[Quantity_Sold]),Table14[[#This Row],[Quantity_Sold]]) -> 2 | G4551: =TRIM(Table14[[#This Row],[Product_Category]]) -> Furniture | H4551: 3322.09 | I4551: 4259.02 | J4551: =PROPER(Table14[[#This Row],[Customer_Type]]) -> Returning | K4551: =IF(ISBLANK(Table14[[#This Row],[Discount]]),MEDIAN(Table14[Discount]),Table14[[#This Row],[Discount]]) -> 0.3 | L4551: Credit Card | M4551: Retail

Sheet KPI cards
A1: Total sales | B1: =SUM('Cleaned Sales'!E2:E4551) -> 3.2085111e+08
A2: Total Orders | B2: =COUNTA('Cleaned Sales'!A2:A4551) -> 4550
A3: AVG discount | B3: =AVERAGE('Cleaned Sales'!K2:K4551) -> 0.1503033
A4: Top selling category | B4: =INDEX('Sales by product category'!A4:A7,MATCH(MAX('Sales by product category'!B4:B7),'Sales by product category'!B4:B7,0)) -> Electronics
A5: Average Order Value | B5: =AVERAGE('Cleaned Sales'!E2:E4551) -> 70516.729

Sheet Cleaned Using formulas
A1: Product_ID | B1: Sale_Date | C1: Sales_Rep | D1: Region | E1: Sales_Amount | F1: Quantity_Sold | G1: Product_Category | H1: Unit_Cost | I1: Unit_Price | J1: Customer_Type | K1: Discount | L1: Payment_Method | M1: Sales_Channel | N1: Sales_Rep2 | O1: Region | P1: Sales_Amount | Q1: Quantity_Sold | R1: Product_Category | S1: Customer_Type | T1: Discount
A2: 1052 | B2: 45235 | C2: David | D2: East | E2: 71951.51 | F2: 48 | G2: Food | H2: 1147.38 | I2: 1594.67 | J2: ReturninG | K2: 0.06 | L2: Credit Card | M2: Retail | N2: =IF(ISBLANK(Table14[[#This Row],[Sales_Rep]]),"Unknown",Table14[[#This Row],[Sales_Rep]]) -> David | O2: =PROPER(Table14[[#This Row],[Region]]) -> East | P2: =IF(ISBLANK(Table14[[#This Row],[Sales_Amount]]),MEDIAN(Table14[Sales_Amount]),Table14[[#This Row],[Sales_Amount]]) -> 71951.51 | Q2: =IF(ISBLANK(Table14[[#This Row],[Quantity_Sold]]),MEDIAN(Table14[Quantity_Sold]),Table14[[#This Row],[Quantity_Sold]]) -> 48 | R2: =TRIM(Table14[[#This Row],[Product_Category]]) -> Food | S2: =PROPER(Table14[[#This Row],[Customer_Type]]) -> Returning | T2: =IF(ISBLANK(Table14[[#This Row],[Discount]]),MEDIAN(Table14[Discount]),Table14[[#This Row],[Discount]]) -> 0.06
A3: 1301 | B3: 45344 | D3: NORTH | E3: 8444.02 | F3: 20 | G3: Electronics | H3: 451.85 | I3: 586.39 | J3: returning | L3: Credit Card | M3: Online | N3: =IF(ISBLANK(Table14[[#This Row],[Sales_Rep]]),"Unknown",Table14[[#This Row],[Sales_Rep]]) -> Unknown | O3: =PROPER(Table14[[#This Row],[Region]]) -> North | P3: =IF(ISBLANK(Table14[[#This Row],[Sales_Amount]]),MEDIAN(Table14[Sales_Amount]),Table14[[#This Row],[Sales_Amount]]) -> 8444.02 | Q3: =IF(ISBLANK(Table14[[#This Row],[Quantity_Sold]]),MEDIAN(Table14[Quantity_Sold]),Table14[[#This Row],[Quantity_Sold]]) -> 20 | R3: =TRIM(Table14[[#This Row],[Product_Category]]) -> Electronics | S3: =PROPER(Table14[[#This Row],[Customer_Type]]) -> Returning | T3: =IF(ISBLANK(Table14[[#This Row],[Discount]]),MEDIAN(Table14[Discount]),Table14[[#This Row],[Discount]]) -> 0.15
A4: 1426 | B4: 44955 | C4: Charlie | D4: East | F4: 36 | G4: Clothing | H4: 1554.12 | I4: 2130.42 | J4: New | K4: 0.28 | L4: Bank Transfer | M4: Retail | N4: =IF(ISBLANK(Table14[[#This Row],[Sales_Rep]]),"Unknown",Table14[[#This Row],[Sales_Rep]]) -> Charlie | O4: =PROPER(Table14[[#This Row],[Region]]) -> East | P4: =IF(ISBLANK(Table14[[#This Row],[Sales_Amount]]),MEDIAN(Table14[Sales_Amount]),Table14[[#This Row],[Sales_Amount]]) -> 50770.89 | Q4: =IF(ISBLANK(Table14[[#This Row],[Quantity_Sold]]),MEDIAN(Table14[Quantity_Sold]),Table14[[#This Row],[Quantity_Sold]]) -> 36 | R4: =TRIM(Table14[[#This Row],[Product_Category]]) -> Clothing | S4: =PROPER(Table14[[#This Row],[Customer_Type]]) -> New | T4: =IF(ISBLANK(Table14[[#This Row],[Discount]]),MEDIAN(Table14[Discount]),Table14[[#This Row],[Discount]]) -> 0.28
A5: 1170 | B5: 44981 | C5: Eve | D5: West | E5: 73691.05 | G5: Clothing | H5: 1733.8 | I5: 2477.01 | J5: rEturning | K5: 0.15 | L5: Credit Card | M5: Online | N5: =IF(ISBLANK(Table14[[#This Row],[Sales_Rep]]),"Unknown",Table14[[#This Row],[Sales_Rep]]) -> Eve | O5: =PROPER(Table14[[#This Row],[Region]]) -> West | P5: =IF(ISBLANK(Table14[[#This Row],[Sales_Amount]]),MEDIAN(Table14[Sales_Amount]),Table14[[#This Row],[Sales_Amount]]) -> 73691.05 | Q5: =IF(ISBLANK(Table14[[#This Row],[Quantity_Sold]]),MEDIAN(Table14[Quantity_Sold]),Table14[[#This Row],[Quantity_Sold]]) -> 25 | R5: =TRIM(Table14[[#This Row],[Product_Category]]) -> Clothing | S5: =PROPER(Table14[[#This Row],[Customer_Type]]) -> Returning | T5: =IF(ISBLANK(Table14[[#This Row],[Discount]]),MEDIAN(Table14[Discount]),Table14[[#This Row],[Discount]]) -> 0.15
A6: 1019 | B6: 45263 | C6: Eve | D6: East | E6: 99978.16 | F6: 33 | G6: Furniture | H6: 2593.01 | I6: 3650.17 | J6: Returning | K6: 0.17 | L6: Credit Card | M6: Retail | N6: =IF(ISBLANK(Table14[[#This Row],[Sales_Rep]]),"Unknown",Table14[[#This Row],[Sales_Rep]]) -> Eve | O6: =PROPER(Table14[[#This Row],[Region]]) -> East | P6: =IF(ISBLANK(Table14[[#This Row],[Sales_Amount]]),MEDIAN(Table14[Sales_Amount]),Table14[[#This Row],[Sales_Amount]]) -> 99978.16 | Q6: =IF(ISBLANK(Table14[[#This Row],[Quantity_Sold]]),MEDIAN(Table14[Quantity_Sold]),Table14[[#This Row],[Quantity_Sold]]) -> 33 | R6: =TRIM(Table14[[#This Row],[Product_Category]]) -> Furniture | S6: =PROPER(Table14[[#This Row],[Customer_Type]]) -> Returning | T6: =IF(ISBLANK(Table14[[#This Row],[Discount]]),MEDIAN(Table14[Discount]),Table14[[#This Row],[Discount]]) -> 0.17
A7: 1239 | B7: 45630 | C7: Bob | D7: NORTH | E7: 18064.11 | F7: 12 | G7: Clothing | H7: 1528.85 | I7: 1954.99 | J7: new | K7: 0.23 | L7: Bank Transfer | M7: Retail | N7: =IF(ISBLANK(Table14[[#This Row],[Sales_Rep]]),"Unknown",Table14[[#This Row],[Sales_Rep]]) -> Bob | O7: =PROPER(Table14[[#This Row],[Region]]) -> North | P7: =IF(ISBLANK(Table14[[#This Row],[Sales_Amount]]),MEDIAN(Table14[Sales_Amount]),Table14[[#This Row],[Sales_Amount]]) -> 18064.11 | Q7: =IF(ISBLANK(Table14[[#This Row],[Quantity_Sold]]),MEDIAN(Table14[Quantity_Sold]),Table14[[#This Row],[Quantity_Sold]]) -> 12 | R7: =TRIM(Table14[[#This Row],[Product_Category]]) -> Clothing | S7: =PROPER(Table14[[#This Row],[Customer_Type]]) -> New | T7: =IF(ISBLANK(Table14[[#This Row],[Discount]]),MEDIAN(Table14[Discount]),Table14[[#This Row],[Discount]]) -> 0.23
A8: 1452 | B8: 45010 | D8: East | E8: 61782.11 | F8: 15 | G8: Food | H8: 4099.54 | I8: 5213.68 | J8: returning | K8: 0.21 | L8: Credit Card | M8: Retail | N8: =IF(ISBLANK(Table14[[#This Row],[Sales_Rep]]),"Unknown",Table14[[#This Row],[Sales_Rep]]) -> Unknown | O8: =PROPER(Table14[[#This Row],[Region]]) -> East | P8: =IF(ISBLANK(Table14[[#This Row],[Sales_Amount]]),MEDIAN(Table14[Sales_Amount]),Table14[[#This Row],[Sales_Amount]]) -> 61782.11 | Q8: =IF(ISBLANK(Table14[[#This Row],[Quantity_Sold]]),MEDIAN(Table14[Quantity_Sold]),Table14[[#This Row],[Quantity_Sold]]) -> 15 | R8: =TRIM(Table14[[#This Row],[Product_Category]]) -> Food | S8: =PROPER(Table14[[#This Row],[Customer_Type]]) -> Returning | T8: =IF(ISBLANK(Table14[[#This Row],[Discount]]),MEDIAN(Table14[Discount]),Table14[[#This Row],[Discount]]) -> 0.21
A9: 1318 | B9: 45124 | C9: Charlie | D9: east | E9: 160204.34 | F9: 45 | G9: Food | H9: 2736.72 | I9: 3747.47 | J9: NeW | L9: Credit Card | M9: Online | N9: =IF(ISBLANK(Table14[[#This Row],[Sales_Rep]]),"Unknown",Table14[[#This Row],[Sales_Rep]]) -> Charlie | O9: =PROPER(Table14[[#This Row],[Region]]) -> East | P9: =IF(ISBLANK(Table14[[#This Row],[Sales_Amount]]),MEDIAN(Table14[Sales_Amount]),Table14[[#This Row],[Sales_Amount]]) -> 160204.34 | Q9: =IF(ISBLANK(Table14[[#This Row],[Quantity_Sold]]),MEDIAN(Table14[Quantity_Sold]),Table14[[#This Row],[Quantity_Sold]]) -> 45 | R9: =TRIM(Table14[[#This Row],[Product_Category]]) -> Food | S9: =PROPER(Table14[[#This Row],[Customer_Type]]) -> New | T9: =IF(ISBLANK(Table14[[#This Row],[Discount]]),MEDIAN(Table14[Discount]),Table14[[#This Row],[Discount]]) -> 0.15
A10: 1463 | B10: 45192 | C10: Charlie | D10: East | E10: 29967.11 | F10: 18 | G10: Electronics | H10: 1686.82 | I10: 1935.86 | J10: Returning | L10: Bank Transfer | M10: Online | N10: =IF(ISBLANK(Table14[[#This Row],[Sales_Rep]]),"Unknown",Table14[[#This Row],[Sales_Rep]]) -> Charlie | O10: =PROPER(Table14[[#This Row],[Region]]) -> East | P10: =IF(ISBLANK(Table14[[#This Row],[Sales_Amount]]),MEDIAN(Table14[Sales_Amount]),Table14[[#This Row],[Sales_Amount]]) -> 29967.11 | Q10: =IF(ISBLANK(Table14[[#This Row],[Quantity_Sold]]),MEDIAN(Table14[Quantity_Sold]),Table14[[#This Row],[Quantity_Sold]]) -> 18 | R10: =TRIM(Table14[[#This Row],[Product_Category]]) -> Electronics | S10: =PROPER(Table14[[#This Row],[Customer_Type]]) -> Returning | T10: =IF(ISBLANK(Table14[[#This Row],[Discount]]),MEDIAN(Table14[Discount]),Table14[[#This Row],[Discount]]) -> 0.15
A11: 1427 | B11: 45297 | C11: Eve | D11: West | E11: 68837.01 | F11: 28 | G11: Food | H11: 2549.57 | I11: 3367.76 | J11: returning | K11: 0.27 | L11: Credit Card | M11: Retail | N11: =IF(ISBLANK(Table14[[#This Row],[Sales_Rep]]),"Unknown",Table14[[#This Row],[Sales_Rep]]) -> Eve | O11: =PROPER(Table14[[#This Row],[Region]]) -> West | P11: =IF(ISBLANK(Table14[[#This Row],[Sales_Amount]]),MEDIAN(Table14[Sales_Amount]),Table14[[#This Row],[Sales_Amount]]) -> 68837.01 | Q11: =IF(ISBLANK(Table14[[#This Row],[Quantity_Sold]]),MEDIAN(Table14[Quantity_Sold]),Table14[[#This Row],[Quantity_Sold]]) -> 28 | R11: =TRIM(Table14[[#This Row],[Product_Category]]) -> Food | S11: =PROPER(Table14[[#This Row],[Customer_Type]]) -> Returning | T11: =IF(ISBLANK(Table14[[#This Row],[Discount]]),MEDIAN(Table14[Discount]),Table14[[#This Row],[Discount]]) -> 0.27
A12: 1455 | B12: 45319 | C12: David | D12: SOuth | F12: 50 | G12: Clothing | H12: 3254.81 | I12: 4805.11 | J12: ReturninG | K12: 0.17 | L12: Cash | M12: Retail | N12: =IF(ISBLANK(Table14[[#This Row],[Sales_Rep]]),"Unknown",Table14[[#This Row],[Sales_Rep]]) -> David | O12: =PROPER(Table14[[#This Row],[Region]]) -> South | P12: =IF(ISBLANK(Table14[[#This Row],[Sales_Amount]]),MEDIAN(Table14[Sales_Amount]),Table14[[#This Row],[Sales_Amount]]) -> 50770.89 | Q12: =IF(ISBLANK(Table14[[#This Row],[Quantity_Sold]]),MEDIAN(Table14[Quantity_Sold]),Table14[[#This Row],[Quantity_Sold]]) -> 50 | R12: =TRIM(Table14[[#This Row],[Product_Category]]) -> Clothing | S12: =PROPER(Table14[[#This Row],[Customer_Type]]) -> Returning | T12: =IF(ISBLANK(Table14[[#This Row],[Discount]]),MEDIAN(Table14[Discount]),Table14[[#This Row],[Discount]]) -> 0.17
A13: 1409 | B13: 45318 | D13: South | E13: 4650.09 | G13: Electronics | H13: 3767.42 | I13: 4744.99 | J13: Returning | K13: 0.02 | L13: Cash | M13: Retail | N13: =IF(ISBLANK(Table14[[#This Row],[Sales_Rep]]),"Unknown",Table14[[#This Row],[Sales_Rep]]) -> Unknown | O13: =PROPER(Table14[[#This Row],[Region]]) -> South | P13: =IF(ISBLANK(Table14[[#This Row],[Sales_Amount]]),MEDIAN(Table14[Sales_Amount]),Table14[[#This Row],[Sales_Amount]]) -> 4650.09 | Q13: =IF(ISBLANK(Table14[[#This Row],[Quantity_Sold]]),MEDIAN(Table14[Quantity_Sold]),Table14[[#This Row],[Quantity_Sold]]) -> 25 | R13: =TRIM(Table14[[#This Row],[Product_Category]]) -> Electronics | S13: =PROPER(Table14[[#This Row],[Customer_Type]]) -> Returning | T13: =IF(ISBLANK(Table14[[#This Row],[Discount]]),MEDIAN(Table14[Discount]),Table14[[#This Row],[Discount]]) -> 0.02
A14: 1169 | B14: 45480 | C14: Eve | D14: WEST | E14: 38774.35 | F14: 49 | G14: Furniture | H14: 803.61 | I14: 976.93 | J14: new | K14: 0.19 | L14: Cash | M14: Retail | N14: =IF(ISBLANK(Table14[[#This Row],[Sales_Rep]]),"Unknown",Table14[[#This Row],[Sales_Rep]]) -> Eve | O14: =PROPER(Table14[[#This Row],[Region]]) -> West | P14: =IF(ISBLANK(Table14[[#This Row],[Sales_Amount]]),MEDIAN(Table14[Sales_Amount]),Table14[[#This Row],[Sales_Amount]]) -> 38774.35 | Q14: =IF(ISBLANK(Table14[[#This Row],[Quantity_Sold]]),MEDIAN(Table14[Quantity_Sold]),Table14[[#This Row],[Quantity_Sold]]) -> 49 | R14: =TRIM(Table14[[#This Row],[Product_Category]]) -> Furniture | S14: =PROPER(Table14[[#This Row],[Customer_Type]]) -> New | T14: =IF(ISBLANK(Table14[[#This Row],[Discount]]),MEDIAN(Table14[Discount]),Table14[[#This Row],[Discount]]) -> 0.19
A15: 1177 | B15: 45506 | C15: Bob | D15: NORTH | E15: 50873.54 | F15: 15 | G15: Food | H15: 2693.32 | I15: 3768.41 | J15: New | K15: 0.1 | L15: Cash | M15: Online | N15: =IF(ISBLANK(Table14[[#This Row],[Sales_Rep]]),"Unknown",Table14[[#This Row],[Sales_Rep]]) -> Bob | O15: =PROPER(Table14[[#This Row],[Region]]) -> North | P15: =IF(ISBLANK(Table14[[#This Row],[Sales_Amount]]),MEDIAN(Table14[Sales_Amount]),Table14[[#This Row],[Sales_Amount]]) -> 50873.54 | Q15: =IF(ISBLANK(Table14[[#This Row],[Quantity_Sold]]),MEDIAN(Table14[Quantity_Sold]),Table14[[#This Row],[Quantity_Sold]]) -> 15 | R15: =TRIM(Table14[[#This Row],[Product_Category]]) -> Food | S15: =PROPER(Table14[[#This Row],[Customer_Type]]) -> New | T15: =IF(ISBLANK(Table14[[#This Row],[Discount]]),MEDIAN(Table14[Discount]),Table14[[#This Row],[Discount]]) -> 0.1
A16: 1060 | B16: 45151 | C16: David | D16: East | E16: 84654.2 | F16: 27 | G16: Electronics | H16: 3628.69 | I16: 4354.64 | J16: New | K16: 0.28 | L16: Credit Card | M16: Online | N16: =IF(ISBLANK(Table14[[#This Row],[Sales_Rep]]),"Unknown",Table14[[#This Row],[Sales_Rep]]) -> David | O16: =PROPER(Table14[[#This Row],[Region]]) -> East | P16: =IF(ISBLANK(Table14[[#This Row],[Sales_Amount]]),MEDIAN(Table14[Sales_Amount]),Table14[[#This Row],[Sales_Amount]]) -> 84654.2 | Q16: =IF(ISBLANK(Table14[[#This Row],[Quantity_Sold]]),MEDIAN(Table14[Quantity_Sold]),Table14[[#This Row],[Quantity_Sold]]) -> 27 | R16: =TRIM(Table14[[#This Row],[Product_Category]]) -> Electronics | S16: =PROPER(Table14[[#This Row],[Customer_Type]]) -> New | T16: =IF(ISBLANK(Table14[[#This Row],[Discount]]),MEDIAN(Table14[Discount]),Table14[[#This Row],[Discount]]) -> 0.28
A17: 1159 | B17: 44940 | C17: Bob | D17: East | F17: 6 | G17: Electronics | H17: 2645.44 | I17: 3000.09 | J17: ReturninG | K17: 0.15 | L17: Bank Transfer | M17: Online | N17: =IF(ISBLANK(Table14[[#This Row],[Sales_Rep]]),"Unknown",Table14[[#This Row],[Sales_Rep]]) -> Bob | O17: =PROPER(Table14[[#This Row],[Region]]) -> East | P17: =IF(ISBLANK(Table14[[#This Row],[Sales_Amount]]),MEDIAN(Table14[Sales_Amount]),Table14[[#This Row],[Sales_Amount]]) -> 50770.89 | Q17: =IF(ISBLANK(Table14[[#This Row],[Quantity_Sold]]),MEDIAN(Table14[Quantity_Sold]),Table14[[#This Row],[Quantity_Sold]]) -> 6 | R17: =TRIM(Table14[[#This Row],[Product_Category]]) -> Electronics | S17: =PROPER(Table14[[#This Row],[Customer_Type]]) -> Returning | T17: =IF(ISBLANK(Table14[[#This Row],[Discount]]),MEDIAN(Table14[Discount]),Table14[[#This Row],[Discount]]) -> 0.15
A18: 1139 | B18: 45154 | C18: David | D18: East | E18: 5218.69 | F18: 2 | G18: Electronics | H18: 2389.48 | I18: 2899.27 | J18: Returning | K18: 0.1 | L18: Bank Transfer | M18: Online | N18: =IF(ISBLANK(Table14[[#This Row],[Sales_Rep]]),"Unknown",Table14[[#This Row],[Sales_Rep]]) -> David | O18: =PROPER(Table14[[#This Row],[Region]]) -> East | P18: =IF(ISBLANK(Table14[[#This Row],[Sales_Amount]]),MEDIAN(Table14[Sales_Amount]),Table14[[#This Row],[Sales_Amount]]) -> 5218.69 | Q18: =IF(ISBLANK(Table14[[#This Row],[Quantity_Sold]]),MEDIAN(Table14[Quantity_Sold]),Table14[[#This Row],[Quantity_Sold]]) -> 2 | R18: =TRIM(Table14[[#This Row],[Product_Category]]) -> Electronics | S18: =PROPER(Table14[[#This Row],[Customer_Type]]) -> Returning | T18: =IF(ISBLANK(Table14[[#This Row],[Discount]]),MEDIAN(Table14[Discount]),Table14[[#This Row],[Discount]]) -> 0.1
A19: 1053 | B19: 44962 | D19: South | E19: 11615 | F19: 12 | G19: Furniture | H19: 882.08 | I19: 987.67 | J19: New | K19: 0.02 | L19: Bank Transfer | M19: Online | N19: =IF(ISBLANK(Table14[[#This Row],[Sales_Rep]]),"Unknown",Table14[[#This Row],[Sales_Rep]]) -> Unknown | O19: =PROPER(Table14[[#This Row],[Region]]) -> South | P19: =IF(ISBLANK(Table14[[#This Row],[Sales_Amount]]),MEDIAN(Table14[Sales_Amount]),Table14[[#This Row],[Sales_Amount]]) -> 11615 | Q19: =IF(ISBLANK(Table14[[#This Row],[Quantity_Sold]]),MEDIAN(Table14[Quantity_Sold]),Table14[[#This Row],[Quantity_Sold]]) -> 12 | R19: =TRIM(Table14[[#This Row],[Product_Category]]) -> Furniture | S19: =PROPER(Table14[[#This Row],[Customer_Type]]) -> New | T19: =IF(ISBLANK(Table14[[#This Row],[Discount]]),MEDIAN(Table14[Discount]),Table14[[#This Row],[Discount]]) -> 0.02
A20: 1426 | B20: 45309 | D20: SOUTH | E20: 25621.81 | F20: 8 | G20: Food | H20: 2968.82 | I20: 4106.06 | J20: Returning | K20: 0.22 | L20: Cash | M20: Online | N20: =IF(ISBLANK(Table14[[#This Row],[Sales_Rep]]),"Unknown",Table14[[#This Row],[Sales_Rep]]) -> Unknown | O20: =PROPER(Table14[[#This Row],[Region]]) -> South | P20: =IF(ISBLANK(Table14[[#This Row],[Sales_Amount]]),MEDIAN(Table14[Sales_Amount]),Table14[[#This Row],[Sales_Amount]]) -> 25621.81 | Q20: =IF(ISBLANK(Table14[[#This Row],[Quantity_Sold]]),MEDIAN(Table14[Quantity_Sold]),Table14[[#This Row],[Quantity_Sold]]) -> 8 | R20: =TRIM(Table14[[#This Row],[Product_Category]]) -> Food | S20: =PROPER(Table14[[#This Row],[Customer_Type]]) -> Returning | T20: =IF(ISBLANK(Table14[[#This Row],[Discount]]),MEDIAN(Table14[Discount]),Table14[[#This Row],[Discount]]) -> 0.22
A21: 1288 | B21: 45369 | C21: David | D21: South | E21: 20271.83 | G21: Electronics | H21: 1329.78 | I21: 1925.15 | J21: returninG | L21: Cash | M21: Online | N21: =IF(ISBLANK(Table14[[#This Row],[Sales_Rep]]),"Unknown",Table14[[#This Row],[Sales_Rep]]) -> David | O21: =PROPER(Table14[[#This Row],[Region]]) -> South | P21: =IF(ISBLANK(Table14[[#This Row],[Sales_Amount]]),MEDIAN(Table14[Sales_Amount]),Table14[[#This Row],[Sales_Amount]]) -> 20271.83 | Q21: =IF(ISBLANK(Table14[[#This Row],[Quantity_Sold]]),MEDIAN(Table14[Quantity_Sold]),Table14[[#This Row],[Quantity_Sold]]) -> 25 | R21: =TRIM(Table14[[#This Row],[Product_Category]]) -> Electronics | S21: =PROPER(Table14[[#This Row],[Customer_Type]]) -> Returning | T21: =IF(ISBLANK(Table14[[#This Row],[Discount]]),MEDIAN(Table14[Discount]),Table14[[#This Row],[Discount]]) -> 0.15
A22: 1337 | B22: 45445 | C22: Bob | D22: East | E22: 7557.82 | G22: Furniture | H22: 915.83 | I22: 1369.17 | J22: Returning | K22: 0.08 | L22: Bank Transfer | M22: Online | N22: =IF(ISBLANK(Table14[[#This Row],[Sales_Rep]]),"Unknown",Table14[[#This Row],[Sales_Rep]]) -> Bob | O22: =PROPER(Table14[[#This Row],[Region]]) -> East | P22: =IF(ISBLANK(Table14[[#This Row],[Sales_Amount]]),MEDIAN(Table14[Sales_Amount]),Table14[[#This Row],[Sales_Amount]]) -> 7557.82 | Q22: =IF(ISBLANK(Table14[[#This Row],[Quantity_Sold]]),MEDIAN(Table14[Quantity_Sold]),Table14[[#This Row],[Quantity_Sold]]) -> 25 | R22: =TRIM(Table14[[#This Row],[Product_Category]]) -> Furniture | S22: =PROPER(Table14[[#This Row],[Customer_Type]]) -> Returning | T22: =IF(ISBLANK(Table14[[#This Row],[Discount]]),MEDIAN(Table14[Discount]),Table14[[#This Row],[Discount]]) -> 0.08
A23: 1319 | B23: 44973 | C23: Eve | D23: East | E23: 112287.09 | F23: 41 | G23: Food | H23: 2844.06 | I23: 3299.65 | J23: New | K23: 0.17 | L23: Cash | M23: Retail | N23: =IF(ISBLANK(Table14[[#This Row],[Sales_Rep]]),"Unknown",Table14[[#This Row],[Sales_Rep]]) -> Eve | O23: =PROPER(Table14[[#This Row],[Region]]) -> East | P23: =IF(ISBLANK(Table14[[#This Row],[Sales_Amount]]),MEDIAN(Table14[Sales_Amount]),Table14[[#This Row],[Sales_Amount]]) -> 112287.09 | Q23: =IF(ISBLANK(Table14[[#This Row],[Quantity_Sold]]),MEDIAN(Table14[Quantity_Sold]),Table14[[#This Row],[Quantity_Sold]]) -> 41 | R23: =TRIM(Table14[[#This Row],[Product_Category]]) -> Food | S23: =PROPER(Table14[[#This Row],[Customer_Type]]) -> New | T23: =IF(ISBLANK(Table14[[#This Row],[Discount]]),MEDIAN(Table14[Discount]),Table14[[#This Row],[Discount]]) -> 0.17
A24: 1205 | B24: 45480 | C24: David | D24: West | E24: 51700.65 | F24: 18 | G24: Furniture | H24: 2763.69 | I24: 3122.02 | J24: New | K24: 0.08 | L24: Cash | M24: Online | N24: =IF(ISBLANK(Table14[[#This Row],[Sales_Rep]]),"Unknown",Table14[[#This Row],[Sales_Rep]]) -> David | O24: =PROPER(Table14[[#This Row],[Region]]) -> West | P24: =IF(ISBLANK(Table14[[#This Row],[Sales_Amount]]),MEDIAN(Table14[Sales_Amount]),Table14[[#This Row],[Sales_Amount]]) -> 51700.65 | Q24: =IF(ISBLANK(Table14[[#This Row],[Quantity_Sold]]),MEDIAN(Table14[Quantity_Sold]),Table14[[#This Row],[Quantity_Sold]]) -> 18 | R24: =TRIM(Table14[[#This Row],[Product_Category]]) -> Furniture | S24: =PROPER(Table14[[#This Row],[Customer_Type]]) -> New | T24: =IF(ISBLANK(Table14[[#This Row],[Discount]]),MEDIAN(Table14[Discount]),Table14[[#This Row],[Discount]]) -> 0.08
A25: 1434 | B25: 45344 | C25: Alice | D25: NORTH | E25: 9329.9 | F25: 6 | G25: Furniture | H25: 1518.93 | I25: 2046.03 | J25: Returning | K25: 0.24 | L25: Bank Transfer | M25: Retail | N25: =IF(ISBLANK(Table14[[#This Row],[Sales_Rep]]),"Unknown",Table14[[#This Row],[Sales_Rep]]) -> Alice | O25: =PROPER(Table14[[#This Row],[Region]]) -> North | P25: =IF(ISBLANK(Table14[[#This Row],[Sales_Amount]]),MEDIAN(Table14[Sales_Amount]),Table14[[#This Row],[Sales_Amount]]) -> 9329.9 | Q25: =IF(ISBLANK(Table14[[#This Row],[Quantity_Sold]]),MEDIAN(Table14[Quantity_Sold]),Table14[[#This Row],[Quantity_Sold]]) -> 6 | R25: =TRIM(Table14[[#This Row],[Product_Category]]) -> Furniture | S25: =PROPER(Table14[[#This Row],[Customer_Type]]) -> Returning | T25: =IF(ISBLANK(Table14[[#This Row],[Discount]]),MEDIAN(Table14[Discount]),Table14[[#This Row],[Discount]]) -> 0.24
A26: 1322 | B26: 45003 | C26: Alice | D26: East | E26: 11086.23 | F26: 3 | G26: Furniture | H26: 2993.59 | I26: 4060.89 | J26: New | K26: 0.09 | L26: Bank Transfer | M26: Online | N26: =IF(ISBLANK(Table14[[#This Row],[Sales_Rep]]),"Unknown",Table14[[#This Row],[Sales_Rep]]) -> Alice | O26: =PROPER(Table14[[#This Row],[Region]]) -> East | P26: =IF(ISBLANK(Table14[[#This Row],[Sales_Amount]]),MEDIAN(Table14[Sales_Amount]),Table14[[#This Row],[Sales_Amount]]) -> 11086.23 | Q26: =IF(ISBLANK(Table14[[#This Row],[Quantity_Sold]]),MEDIAN(Table14[Quantity_Sold]),Table14[[#This Row],[Quantity_Sold]]) -> 3 | R26: =TRIM(Table14[[#This Row],[Product_Category]]) -> Furniture | S26: =PROPER(Table14[[#This Row],[Customer_Type]]) -> New | T26: =IF(ISBLANK(Table14[[#This Row],[Discount]]),MEDIAN(Table14[Discount]),Table14[[#This Row],[Discount]]) -> 0.09
A27: 1165 | B27: 45143 | C27: Charlie | D27: South | E27: 2639.43 | F27: 18 | G27: Furniture | H27: 151.27 | I27: 203.66 | J27: new | K27: 0.28 | L27: Bank Transfer | M27: Retail | N27: =IF(ISBLANK(Table14[[#This Row],[Sales_Rep]]),"Unknown",Table14[[#This Row],[Sales_Rep]]) -> Charlie | O27: =PROPER(Table14[[#This Row],[Region]]) -> South | P27: =IF(ISBLANK(Table14[[#This Row],[Sales_Amount]]),MEDIAN(Table14[Sales_Amount]),Table14[[#This Row],[Sales_Amount]]) -> 2639.43 | Q27: =IF(ISBLANK(Table14[[#This Row],[Quantity_Sold]]),MEDIAN(Table14[Quantity_Sold]),Table14[[#This Row],[Quantity_Sold]]) -> 18 | R27: =TRIM(Table14[[#This Row],[Product_Category]]) -> Furniture | S27: =PROPER(Table14[[#This Row],[Customer_Type]]) -> New | T27: =IF(ISBLANK(Table14[[#This Row],[Discount]]),MEDIAN(Table14[Discount]),Table14[[#This Row],[Discount]]) -> 0.28
A28: 1154 | B28: 45618 | C28: Charlie | D28: West | E28: 26058.24 | F28: 24 | G28: Food | H28: 952.7 | I28: 1392 | J28: New | K28: 0.22 | L28: Bank Transfer | M28: Online | N28: =IF(ISBLANK(Table14[[#This Row],[Sales_Rep]]),"Unknown",Table14[[#This Row],[Sales_Rep]]) -> Charlie | O28: =PROPER(Table14[[#This Row],[Region]]) -> West | P28: =IF(ISBLANK(Table14[[#This Row],[Sales_Amount]]),MEDIAN(Table14[Sales_Amount]),Table14[[#This Row],[Sales_Amount]]) -> 26058.24 | Q28: =IF(ISBLANK(Table14[[#This Row],[Quantity_Sold]]),MEDIAN(Table14[Quantity_Sold]),Table14[[#This Row],[Quantity_Sold]]) -> 24 | R28: =TRIM(Table14[[#This Row],[Product_Category]]) -> Food | S28: =PROPER(Table14[[#This Row],[Customer_Type]]) -> New | T28: =IF(ISBLANK(Table14[[#This Row],[Discount]]),MEDIAN(Table14[Discount]),Table14[[#This Row],[Discount]]) -> 0.22
A29: 1103 | B29: 44933 | D29: East | E29: 16454.74 | F29: 6 | G29: Electronics | H29: 2449.66 | I29: 3515.97 | J29: New | K29: 0.22 | L29: Cash | M29: Online | N29: =IF(ISBLANK(Table14[[#This Row],[Sales_Rep]]),"Unknown",Table14[[#This Row],[Sales_Rep]]) -> Unknown | O29: =PROPER(Table14[[#This Row],[Region]]) -> East | P29: =IF(ISBLANK(Table14[[#This Row],[Sales_Amount]]),MEDIAN(Table14[Sales_Amount]),Table14[[#This Row],[Sales_Amount]]) -> 16454.74 | Q29: =IF(ISBLANK(Table14[[#This Row],[Quantity_Sold]]),MEDIAN(Table14[Quantity_Sold]),Table14[[#This Row],[Quantity_Sold]]) -> 6 | R29: =TRIM(Table14[[#This Row],[Product_Category]]) -> Electronics | S29: =PROPER(Table14[[#This Row],[Customer_Type]]) -> New | T29: =IF(ISBLANK(Table14[[#This Row],[Discount]]),MEDIAN(Table14[Discount]),Table14[[#This Row],[Discount]]) -> 0.22
A30: 1003 | B30: 45142 | C30: David | D30: West | E30: 2136.41 | F30: 13 | G30: Electronics | H30: 149.55 | I30: 193.34 | J30: new | K30: 0.15 | L30: Cash | M30: Online | N30: =IF(ISBLANK(Table14[[#This Row],[Sales_Rep]]),"Unknown",Table14[[#This Row],[Sales_Rep]]) -> David | O30: =PROPER(Table14[[#This Row],[Region]]) -> West | P30: =IF(ISBLANK(Table14[[#This Row],[Sales_Amount]]),MEDIAN(Table14[Sales_Amount]),Table14[[#This Row],[Sales_Amount]]) -> 2136.41 | Q30: =IF(ISBLANK(Table14[[#This Row],[Quantity_Sold]]),MEDIAN(Table14[Quantity_Sold]),Table14[[#This Row],[Quantity_Sold]]) -> 13 | R30: =TRIM(Table14[[#This Row],[Product_Category]]) -> Electronics | S30: =PROPER(Table14[[#This Row],[Customer_Type]]) -> New | T30: =IF(ISBLANK(Table14[[#This Row],[Discount]]),MEDIAN(Table14[Discount]),Table14[[#This Row],[Discount]]) -> 0.15
A31: 1067 | B31: 45462 | C31: David | D31: North | E31: 264002.31 | F31: 39 | G31: Clothing | H31: 4707.48 | I31: 6769.29 | J31: Returning | K31: 0 | L31: Credit Card | M31: Retail | N31: =IF(ISBLANK(Table14[[#This Row],[Sales_Rep]]),"Unknown",Table14[[#This Row],[Sales_Rep]]) -> David | O31: =PROPER(Table14[[#This Row],[Region]]) -> North | P31: =IF(ISBLANK(Table14[[#This Row],[Sales_Amount]]),MEDIAN(Table14[Sales_Amount]),Table14[[#This Row],[Sales_Amount]]) -> 264002.31 | Q31: =IF(ISBLANK(Table14[[#This Row],[Quantity_Sold]]),MEDIAN(Table14[Quantity_Sold]),Table14[[#This Row],[Quantity_Sold]]) -> 39 | R31: =TRIM(Table14[[#This Row],[Product_Category]]) -> Clothing | S31: =PROPER(Table14[[#This Row],[Customer_Type]]) -> Returning | T31: =IF(ISBLANK(Table14[[#This Row],[Discount]]),MEDIAN(Table14[Discount]),Table14[[#This Row],[Discount]]) -> 0
A32: 1332 | B32: 45316 | C32: Charlie | D32: East | E32: 48686.3 | F32: 18 | G32: Clothing | H32: 2779.59 | I32: 3298.53 | J32: Returning | K32: 0.18 | L32: Cash | M32: Retail | N32: =IF(ISBLANK(Table14[[#This Row],[Sales_Rep]]),"Unknown",Table14[[#This Row],[Sales_Rep]]) -> Charlie | O32: =PROPER(Table14[[#This Row],[Region]]) -> East | P32: =IF(ISBLANK(Table14[[#This Row],[Sales_Amount]]),MEDIAN(Table14[Sales_Amount]),Table14[[#This Row],[Sales_Amount]]) -> 48686.3 | Q32: =IF(ISBLANK(Table14[[#This Row],[Quantity_Sold]]),MEDIAN(Table14[Quantity_Sold]),Table14[[#This Row],[Quantity_Sold]]) -> 18 | R32: =TRIM(Table14[[#This Row],[Product_Category]]) -> Clothing | S32: =PROPER(Table14[[#This Row],[Customer_Type]]) -> Returning | T32: =IF(ISBLANK(Table14[[#This Row],[Discount]]),MEDIAN(Table14[Discount]),Table14[[#This Row],[Discount]]) -> 0.18
A33: 1308 | B33: 45051 | C33: David | D33: SOUTH | E33: 6882.52 | F33: 7 | G33: Furniture | H33: 1187.82 | I33: 1365.58 | J33: New | K33: 0.28 | L33: Bank Transfer | M33: Retail | N33: =IF(ISBLANK(Table14[[#This Row],[Sales_Rep]]),"Unknown",Table14[[#This Row],[Sales_Rep]]) -> David | O33: =PROPER(Table14[[#This Row],[Region]]) -> South | P33: =IF(ISBLANK(Table14[[#This Row],[Sales_Amount]]),MEDIAN(Table14[Sales_Amount]),Table14[[#This Row],[Sales_Amount]]) -> 6882.52 | Q33: =IF(ISBLANK(Table14[[#This Row],[Quantity_Sold]]),MEDIAN(Table14[Quantity_Sold]),Table14[[#This Row],[Quantity_Sold]]) -> 7 | R33: =TRIM(Table14[[#This Row],[Product_Category]]) -> Furniture | S33: =PROPER(Table14[[#This Row],[Customer_Type]]) -> New | T33: =IF(ISBLANK(Table14[[#This Row],[Discount]]),MEDIAN(Table14[Discount]),Table14[[#This Row],[Discount]]) -> 0.28
A34: 1421 | B34: 45220 | C34: David | D34: East | E34: 117576.01 | F34: 37 | G34: Furniture | H34: 2209.4 | I34: 3177.73 | J34: Returning | K34: 0 | L34: Bank Transfer | M34: Online | N34: =IF(ISBLANK(Table14[[#This Row],[Sales_Rep]]),"Unknown",Table14[[#This Row],[Sales_Rep]]) -> David | O34: =PROPER(Table14[[#This Row],[Region]]) -> East | P34: =IF(ISBLANK(Table14[[#This Row],[Sales_Amount]]),MEDIAN(Table14[Sales_Amount]),Table14[[#This Row],[Sales_Amount]]) -> 117576.01 | Q34: =IF(ISBLANK(Table14[[#This Row],[Quantity_Sold]]),MEDIAN(Table14[Quantity_Sold]),Table14[[#This Row],[Quantity_Sold]]) -> 37 | R34: =TRIM(Table14[[#This Row],[Product_Category]]) -> Furniture | S34: =PROPER(Table14[[#This Row],[Customer_Type]]) -> Returning | T34: =IF(ISBLANK(Table14[[#This Row],[Discount]]),MEDIAN(Table14[Discount]),Table14[[#This Row],[Discount]]) -> 0
A35: 1088 | B35: 45100 | C35: Alice | D35: west | E35: 3588.45 | F35: 4 | G35: Food | H35: 905.02 | I35: 1196.15 | J35: New | K35: 0.25 | L35: Bank Transfer | M35: Retail | N35: =IF(ISBLANK(Table14[[#This Row],[Sales_Rep]]),"Unknown",Table14[[#This Row],[Sales_Rep]]) -> Alice | O35: =PROPER(Table14[[#This Row],[Region]]) -> West | P35: =IF(ISBLANK(Table14[[#This Row],[Sales_Amount]]),MEDIAN(Table14[Sales_Amount]),Table14[[#This Row],[Sales_Amount]]) -> 3588.45 | Q35: =IF(ISBLANK(Table14[[#This Row],[Quantity_Sold]]),MEDIAN(Table14[Quantity_Sold]),Table14[[#This Row],[Quantity_Sold]]) -> 4 | R35: =TRIM(Table14[[#This Row],[Product_Category]]) -> Food | S35: =PROPER(Table14[[#This Row],[Customer_Type]]) -> New | T35: =IF(ISBLANK(Table14[[#This Row],[Discount]]),MEDIAN(Table14[Discount]),Table14[[#This Row],[Discount]]) -> 0.25
A36: 1166 | B36: 45235 | C36: Charlie | D36: East | E36: 2399.28 | F36: 1 | G36: Clothing | H36: 1991.33 | I36: 2856.29 | J36: new | K36: 0.16 | L36: Bank Transfer | M36: Retail | N36: =IF(ISBLANK(Table14[[#This Row],[Sales_Rep]]),"Unknown",Table14[[#This Row],[Sales_Rep]]) -> Charlie | O36: =PROPER(Table14[[#This Row],[Region]]) -> East | P36: =IF(ISBLANK(Table14[[#This Row],[Sales_Amount]]),MEDIAN(Table14[Sales_Amount]),Table14[[#This Row],[Sales_Amount]]) -> 2399.28 | Q36: =IF(ISBLANK(Table14[[#This Row],[Quantity_Sold]]),MEDIAN(Table14[Quantity_Sold]),Table14[[#This Row],[Quantity_Sold]]) -> 1 | R36: =TRIM(Table14[[#This Row],[Product_Category]]) -> Clothing | S36: =PROPER(Table14[[#This Row],[Customer_Type]]) -> New | T36: =IF(ISBLANK(Table14[[#This Row],[Discount]]),MEDIAN(Table14[Discount]),Table14[[#This Row],[Discount]]) -> 0.16
A37: 1362 | B37: 45068 | C37: Eve | D37: South | E37: 9432.76 | F37: 5 | G37: Furniture | H37: 1527.92 | I37: 2006.97 | J37: New | L37: Cash | M37: Retail | N37: =IF(ISBLANK(Table14[[#This Row],[Sales_Rep]]),"Unknown",Table14[[#This Row],[Sales_Rep]]) -> Eve | O37: =PROPER(Table14[[#This Row],[Region]]) -> South | P37: =IF(ISBLANK(Table14[[#This Row],[Sales_Amount]]),MEDIAN(Table14[Sales_Amount]),Table14[[#This Row],[Sales_Amount]]) -> 9432.76 | Q37: =IF(ISBLANK(Table14[[#This Row],[Quantity_Sold]]),MEDIAN(Table14[Quantity_Sold]),Table14[[#This Row],[Quantity_Sold]]) -> 5 | R37: =TRIM(Table14[[#This Row],[Product_Category]]) -> Furniture | S37: =PROPER(Table14[[#This Row],[Customer_Type]]) -> New | T37: =IF(ISBLANK(Table14[[#This Row],[Discount]]),MEDIAN(Table14[Discount]),Table14[[#This Row],[Discount]]) -> 0.15
A38: 1311 | B38: 45396 | C38: Charlie | D38: South | F38: 39 | G38: Clothing | H38: 3976.45 | I38: 5201.72 | J38: New | K38: 0.18 | L38: Cash | M38: Online | N38: =IF(ISBLANK(Table14[[#This Row],[Sales_Rep]]),"Unknown",Table14[[#This Row],[Sales_Rep]]) -> Charlie | O38: =PROPER(Table14[[#This Row],[Region]]) -> South | P38: =IF(ISBLANK(Table14[[#This Row],[Sales_Amount]]),MEDIAN(Table14[Sales_Amount]),Table14[[#This Row],[Sales_Amount]]) -> 50770.89 | Q38: =IF(ISBLANK(Table14[[#This Row],[Quantity_Sold]]),MEDIAN(Table14[Quantity_Sold]),Table14[[#This Row],[Quantity_Sold]]) -> 39 | R38: =TRIM(Table14[[#This Row],[Product_Category]]) -> Clothing | S38: =PROPER(Table14[[#This Row],[Customer_Type]]) -> New | T38: =IF(ISBLANK(Table14[[#This Row],[Discount]]),MEDIAN(Table14[Discount]),Table14[[#This Row],[Discount]]) -> 0.18
A39: 1038 | B39: 45406 | C39: Eve | D39: West | F39: 24 | G39: Electronics | H39: 2282.47 | I39: 2558.37 | J39: Returning | K39: 0.02 | L39: Cash | M39: Retail | N39: =IF(ISBLANK(Table14[[#This Row],[Sales_Rep]]),"Unknown",Table14[[#This Row],[Sales_Rep]]) -> Eve | O39: =PROPER(Table14[[#This Row],[Region]]) -> West | P39: =IF(ISBLANK(Table14[[#This Row],[Sales_Amount]]),MEDIAN(Table14[Sales_Amount]),Table14[[#This Row],[Sales_Amount]]) -> 50770.89 | Q39: =IF(ISBLANK(Table14[[#This Row],[Quantity_Sold]]),MEDIAN(Table14[Quantity_Sold]),Table14[[#This Row],[Quantity_Sold]]) -> 24 | R39: =TRIM(Table14[[#This Row],[Product_Category]]) -> Electronics | S39: =PROPER(Table14[[#This Row],[Customer_Type]]) -> Returning | T39: =IF(ISBLANK(Table14[[#This Row],[Discount]]),MEDIAN(Table14[Discount]),Table14[[#This Row],[Discount]]) -> 0.02
A40: 1001 | B40: 45614 | C40: Alice | D40: West | E40: 56953.67 | F40: 19 | G40: Electronics | H40: 3366.81 | I40: 4163.28 | J40: New | K40: 0.28 | L40: Credit Card | M40: Retail | N40: =IF(ISBLANK(Table14[[#This Row],[Sales_Rep]]),"Unknown",Table14[[#This Row],[Sales_Rep]]) -> Alice | O40: =PROPER(Table14[[#This Row],[Region]]) -> West | P40: =IF(ISBLANK(Table14[[#This Row],[Sales_Amount]]),MEDIAN(Table14[Sales_Amount]),Table14[[#This Row],[Sales_Amount]]) -> 56953.67 | Q40: =IF(ISBLANK(Table14[[#This Row],[Quantity_Sold]]),MEDIAN(Table14[Quantity_Sold]),Table14[[#This Row],[Quantity_Sold]]) -> 19 | R40: =TRIM(Table14[[#This Row],[Product_Category]]) -> Electronics | S40: =PROPER(Table14[[#This Row],[Customer_Type]]) -> New | T40: =IF(ISBLANK(Table14[[#This Row],[Discount]]),MEDIAN(Table14[Discount]),Table14[[#This Row],[Discount]]) -> 0.28
...

Sheet Retail Sales Orginal
A1: Product_ID | B1: Sale_Date | C1: Sales_Rep | D1: Region | E1: Sales_Amount | F1: Quantity_Sold | G1: Product_Category | H1: Unit_Cost | I1: Unit_Price | J1: Customer_Type | K1: Discount | L1: Payment_Method | M1: Sales_Channel
A2: 1052 | B2: 45235 | C2: David | D2: East | E2: 71951.51 | F2: 48 | G2: Food | H2: 1147.38 | I2: 1594.67 | J2: ReturninG | K2: 0.06 | L2: Credit Card | M2: Retail
A3: 1301 | B3: 45344 | D3: NORTH | E3: 8444.02 | F3: 20 | G3: Electronics | H3: 451.85 | I3: 586.39 | J3: returning | L3: Credit Card | M3: Online
A4: 1426 | B4: 44955 | C4: Charlie | D4: East | F4: 36 | G4: Clothing | H4: 1554.12 | I4: 2130.42 | J4: New | K4: 0.28 | L4: Bank Transfer | M4: Retail
A5: 1170 | B5: 44981 | C5: Eve | D5: West | E5: 73691.05 | G5: Clothing | H5: 1733.8 | I5: 2477.01 | J5: rEturning | K5: 0.15 | L5: Credit Card | M5: Online
A6: 1019 | B6: 45263 | C6: Eve | D6: East | E6: 99978.16 | F6: 33 | G6: Furniture | H6: 2593.01 | I6: 3650.17 | J6: Returning | K6: 0.17 | L6: Credit Card | M6: Retail
A7: 1239 | B7: 45630 | C7: Bob | D7: NORTH | E7: 18064.11 | F7: 12 | G7: Clothing | H7: 1528.85 | I7: 1954.99 | J7: new | K7: 0.23 | L7: Bank Transfer | M7: Retail
A8: 1452 | B8: 45010 | D8: East | E8: 61782.11 | F8: 15 | G8: Food | H8: 4099.54 | I8: 5213.68 | J8: returning | K8: 0.21 | L8: Credit Card | M8: Retail
A9: 1318 | B9: 45124 | C9: Charlie | D9: east | E9: 160204.34 | F9: 45 | G9: Food | H9: 2736.72 | I9: 3747.47 | J9: NeW | L9: Credit Card | M9: Online
A10: 1463 | B10: 45192 | C10: Charlie | D10: East | E10: 29967.11 | F10: 18 | G10: Electronics | H10: 1686.82 | I10: 1935.86 | J10: Returning | L10: Bank Transfer | M10: Online
A11: 1427 | B11: 45297 | C11: Eve | D11: West | E11: 68837.01 | F11: 28 | G11: Food | H11: 2549.57 | I11: 3367.76 | J11: returning | K11: 0.27 | L11: Credit Card | M11: Retail
A12: 1455 | B12: 45319 | C12: David | D12: SOuth | F12: 50 | G12: Clothing | H12: 3254.81 | I12: 4805.11 | J12: ReturninG | K12: 0.17 | L12: Cash | M12: Retail
A13: 1409 | B13: 45318 | D13: South | E13: 4650.09 | G13: Electronics | H13: 3767.42 | I13: 4744.99 | J13: Returning | K13: 0.02 | L13: Cash | M13: Retail
A14: 1169 | B14: 45480 | C14: Eve | D14: WEST | E14: 38774.35 | F14: 49 | G14: Furniture | H14: 803.61 | I14: 976.93 | J14: new | K14: 0.19 | L14: Cash | M14: Retail
A15: 1177 | B15: 45506 | C15: Bob | D15: NORTH | E15: 50873.54 | F15: 15 | G15: Food | H15: 2693.32 | I15: 3768.41 | J15: New | K15: 0.1 | L15: Cash | M15: Online
A16: 1060 | B16: 45151 | C16: David | D16: East | E16: 84654.2 | F16: 27 | G16: Electronics | H16: 3628.69 | I16: 4354.64 | J16: New | K16: 0.28 | L16: Credit Card | M16: Online
A17: 1159 | B17: 44940 | C17: Bob | D17: East | F17: 6 | G17: Electronics | H17: 2645.44 | I17: 3000.09 | J17: ReturninG | K17: 0.15 | L17: Bank Transfer | M17: Online
A18: 1139 | B18: 45154 | C18: David | D18: East | E18: 5218.69 | F18: 2 | G18: Electronics | H18: 2389.48 | I18: 2899.27 | J18: Returning | K18: 0.1 | L18: Bank Transfer | M18: Online
A19: 1053 | B19: 44962 | D19: South | E19: 11615 | F19: 12 | G19: Furniture | H19: 882.08 | I19: 987.67 | J19: New | K19: 0.02 | L19: Bank Transfer | M19: Online
A20: 1426 | B20: 45309 | D20: SOUTH | E20: 25621.81 | F20: 8 | G20: Food | H20: 2968.82 | I20: 4106.06 | J20: Returning | K20: 0.22 | L20: Cash | M20: Online
A21: 1288 | B21: 45369 | C21: David | D21: South | E21: 20271.83 | G21: Electronics | H21: 1329.78 | I21: 1925.15 | J21: returninG | L21: Cash | M21: Online
A22: 1337 | B22: 45445 | C22: Bob | D22: East | E22: 7557.82 | G22: Furniture | H22: 915.83 | I22: 1369.17 | J22: Returning | K22: 0.08 | L22: Bank Transfer | M22: Online
A23: 1319 | B23: 44973 | C23: Eve | D23: East | E23: 112287.09 | F23: 41 | G23: Food | H23: 2844.06 | I23: 3299.65 | J23: New | K23: 0.17 | L23: Cash | M23: Retail
A24: 1205 | B24: 45480 | C24: David | D24: West | E24: 51700.65 | F24: 18 | G24: Furniture | H24: 2763.69 | I24: 3122.02 | J24: New | K24: 0.08 | L24: Cash | M24: Online
A25: 1434 | B25: 45344 | C25: Alice | D25: NORTH | E25: 9329.9 | F25: 6 | G25: Furniture | H25: 1518.93 | I25: 2046.03 | J25: Returning | K25: 0.24 | L25: Bank Transfer | M25: Retail
A26: 1322 | B26: 45003 | C26: Alice | D26: East | E26: 11086.23 | F26: 3 | G26: Furniture | H26: 2993.59 | I26: 4060.89 | J26: New | K26: 0.09 | L26: Bank Transfer | M26: Online
A27: 1165 | B27: 45143 | C27: Charlie | D27: South | E27: 2639.43 | F27: 18 | G27: Furniture | H27: 151.27 | I27: 203.66 | J27: new | K27: 0.28 | L27: Bank Transfer | M27: Retail
A28: 1154 | B28: 45618 | C28: Charlie | D28: West | E28: 26058.24 | F28: 24 | G28: Food | H28: 952.7 | I28: 1392 | J28: New | K28: 0.22 | L28: Bank Transfer | M28: Online
A29: 1103 | B29: 44933 | D29: East | E29: 16454.74 | F29: 6 | G29: Electronics | H29: 2449.66 | I29: 3515.97 | J29: New | K29: 0.22 | L29: Cash | M29: Online
A30: 1003 | B30: 45142 | C30: David | D30: West | E30: 2136.41 | F30: 13 | G30: Electronics | H30: 149.55 | I30: 193.34 | J30: new | K30: 0.15 | L30: Cash | M30: Online
A31: 1067 | B31: 45462 | C31: David | D31: North | E31: 264002.31 | F31: 39 | G31: Clothing | H31: 4707.48 | I31: 6769.29 | J31: Returning | K31: 0 | L31: Credit Card | M31: Retail
